### ✅ `asyncio.TimeoutError` とは？

> **非同期処理が制限時間内に完了しなかったときに発生する例外クラス**です。
> 特に `asyncio.wait_for()` などで **タイムアウトが指定されている場合に自動で発生します**。

---

## ✅ 一言で言えば：

> **「待たされた処理が時間切れになったときに起きるエラー」**。

---

## ✅ 発生する主な場面：`asyncio.wait_for()`

```python
import asyncio

async def long_task():
    await asyncio.sleep(5)

async def main():
    try:
        await asyncio.wait_for(long_task(), timeout=2)
    except asyncio.TimeoutError:
        print("タイムアウト発生")

asyncio.run(main())
```

出力：

```
タイムアウト発生
```

* `sleep(5)` に対して、`timeout=2` なので、**2秒で `TimeoutError` が発生**

---

## ✅ 補足：`asyncio.TimeoutError` は組み込みの `TimeoutError` とは別物

| 名称                     | 属するモジュール     | 用途                   |
| ---------------------- | ------------ | -------------------- |
| `asyncio.TimeoutError` | `asyncio`    | 非同期処理のタイムアウト         |
| `TimeoutError`（組み込み）   | Python組み込み例外 | ファイル・ソケットの同期タイムアウトなど |

```python
import asyncio

try:
    raise asyncio.TimeoutError()
except TimeoutError:
    print("これは asyncio のじゃない方")
```

上記では **捕まらない**（別物だから）。

---

## ✅ よく使う組み合わせ

| 関数名                            | 用途                             |
| ------------------------------ | ------------------------------ |
| `asyncio.wait_for()`           | 任意のコルーチンにタイムアウトを設定する           |
| `asyncio.wait(..., timeout=N)` | 複数タスクのうち、**制限時間までに完了したものだけ回収** |

---

## ✅ 実運用での役割

| シーン                        | 説明                          |
| -------------------------- | --------------------------- |
| API呼び出しの監視                 | 「3秒以内にレスポンスがないならキャンセル」などに使用 |
| 非同期ループの強制打ち切り              | タスクがハングしたときに保険として使う         |
| セマフォやキューの `.get()` の待ち時間制限 | 何も来なければタイムアウトで切り上げたいとき      |

---

## ✅ まとめ

> `asyncio.TimeoutError` は、**非同期処理において時間制限を設けるときに発生する専用の例外クラス**。
> 特に `wait_for()` との併用で使われ、**通信待機・応答監視などの制御構造に不可欠**です。

---

必要であれば、`TimeoutError` を伴う `wait_for()` のリトライ構造、または `asyncio.shield()` を使ってタイムアウトを無視する構成なども提示できます。希望があればどうぞ。
